
import { render, screen, fireEvent } from '@testing-library/react';
import '@testing-library/jest-dom';
import { vi } from 'vitest';
import ErrorBoundary from '../ErrorBoundary';

// Mock component that throws an error
const ThrowError = ({ shouldThrow }: { shouldThrow: boolean }) => {
  if (shouldThrow) {
    throw new Error('Test error');
  }
  return <div>No error</div>;
};

// Mock window.location.reload
const mockReload = vi.fn();
Object.defineProperty(window, 'location', {
  value: {
    reload: mockReload,
  },
  writable: true,
});

describe('ErrorBoundary', () => {
  beforeEach(() => {
    vi.clearAllMocks();
    // Suppress console.error for these tests
    vi.spyOn(console, 'error').mockImplementation(() => {});
  });

  afterEach(() => {
    vi.restoreAllMocks();
  });

  it('renders children when there is no error', () => {
    render(
      <ErrorBoundary>
        <ThrowError shouldThrow={false} />
      </ErrorBoundary>
    );

    expect(screen.getByText('No error')).toBeInTheDocument();
  });

  it('renders error UI when there is an error', () => {
    render(
      <ErrorBoundary>
        <ThrowError shouldThrow={true} />
      </ErrorBoundary>
    );

    expect(screen.getByText('Something went wrong')).toBeInTheDocument();
    expect(screen.getByText(/We're sorry, but something unexpected happened/)).toBeInTheDocument();
    expect(screen.getByRole('button', { name: 'Try Again' })).toBeInTheDocument();
    expect(screen.getByRole('button', { name: 'Reload Page' })).toBeInTheDocument();
  });

  it('renders custom fallback when provided', () => {
    const customFallback = <div>Custom error message</div>;

    render(
      <ErrorBoundary fallback={customFallback}>
        <ThrowError shouldThrow={true} />
      </ErrorBoundary>
    );

    expect(screen.getByText('Custom error message')).toBeInTheDocument();
    expect(screen.queryByText('Something went wrong')).not.toBeInTheDocument();
  });

  it('resets error state when Try Again is clicked', () => {
    render(
      <ErrorBoundary>
        <ThrowError shouldThrow={true} />
      </ErrorBoundary>
    );

    expect(screen.getByText('Something went wrong')).toBeInTheDocument();

    fireEvent.click(screen.getByRole('button', { name: 'Try Again' }));

    // After clicking Try Again, the error boundary should reset its state
    // but since we're still rendering the same error-throwing component,
    // it will immediately error again. This is expected behavior.
    expect(screen.getByText('Something went wrong')).toBeInTheDocument();
  });

  it('reloads page when Reload Page is clicked', () => {
    render(
      <ErrorBoundary>
        <ThrowError shouldThrow={true} />
      </ErrorBoundary>
    );

    fireEvent.click(screen.getByRole('button', { name: 'Reload Page' }));

    expect(mockReload).toHaveBeenCalledTimes(1);
  });

  it('shows error details in development mode', () => {
    const originalEnv = process.env.NODE_ENV;
    process.env.NODE_ENV = 'development';

    render(
      <ErrorBoundary>
        <ThrowError shouldThrow={true} />
      </ErrorBoundary>
    );

    expect(screen.getByText('Error Details (Development)')).toBeInTheDocument();

    process.env.NODE_ENV = originalEnv;
  });

  it('hides error details in production mode', () => {
    const originalEnv = process.env.NODE_ENV;
    process.env.NODE_ENV = 'production';

    render(
      <ErrorBoundary>
        <ThrowError shouldThrow={true} />
      </ErrorBoundary>
    );

    expect(screen.queryByText('Error Details (Development)')).not.toBeInTheDocument();

    process.env.NODE_ENV = originalEnv;
  });

  it('logs error to console', () => {
    const consoleSpy = vi.spyOn(console, 'error').mockImplementation(() => {});

    render(
      <ErrorBoundary>
        <ThrowError shouldThrow={true} />
      </ErrorBoundary>
    );

    expect(consoleSpy).toHaveBeenCalledWith(
      'ErrorBoundary caught an error:',
      expect.any(Error),
      expect.any(Object)
    );
  });
});